<!DOCTYPE html>
<html lang="en">
<head>
    <meta charset="UTF-8">
    <title>promise代码重排</title>
    <script type="text/javascript" src="script/jquery-3.6.0.min.js"></script>
    <script type="text/javascript">

        /* 不是程序发生异常才进入到catch中吗？Promise对象分别进入到.then()和.catch()执行的时机是？
        在 JavaScript 的 `Promise` 对象中，`.then()` 和 `.catch()` 方法被用于处理异步操作的成功结果和失败结果：

        1. **`.then()`**：当 `Promise` 被成功解决（或"fulfilled"）时，`.then()` 方法中的回调函数将被调用。这通常表示异步操作已成功完成，并且可以通过 `.then()` 方法中的回调函数获取到操作的结果。

        2. **`.catch()`**：当 `Promise` 被拒绝（或"rejected"）时，`.catch()` 方法中的回调函数将被调用。这通常表示异步操作失败或出现错误。`Promise` 被拒绝可以由于多种原因，包括手动拒绝（例如，在 `Promise` 内部通过调用 `reject()` 函数）、抛出异常（在 `Promise` 的执行函数或 `.then()` 方法的回调函数中抛出错误）。

        在 `this.$confirm` 的情况中，它使用 `Promise` 来处理用户的交互：

        - 当用户点击“确定”按钮时，`$confirm` 的 `Promise` 被解决，这导致 `.then()` 方法中的回调函数被执行。这里，并不是因为程序没有异常就进入 `.then()`，而是因为对话框的逻辑是当用户确认操作时，视为流程“成功”，从而进入 `.then()`。

        - 当用户点击“取消”按钮或关闭对话框时，`$confirm` 的 `Promise` 被拒绝，这导致 `.catch()` 方法中的回调函数被执行。在这种情况下，进入 `.catch()` 并不意味着程序发生了异常，而是因为按照 `Element UI` 的 `$confirm` 方法的约定，取消操作会拒绝 `Promise`。

        因此，在 `Promise` 的上下文中，"成功" 和 "失败" 并不总是指程序的执行没有错误，而是指异步操作的结果符合或不符合预期。在 `this.$confirm` 的场景中，"成功" 和 "失败" 只是代表用户是确认还是取消了对话框中的操作。
         */

        // 将 重复的代码提取出来 封装成一个方法
        function get(url,data){

          return new Promise((resolve,reject) => {
                $.ajax({
                    url:url,
                    data:data,
                    success(resultData){
                        //console.log(resultData);
                        resolve(resultData);
                    },
                    error(err){
                        //console.log(err);
                        reject(err);
                    }
                })
            })
        }


        get("data/monster.json").then((resultData) => {
        //下面这种写法也可以
        //get("http://localhost:57823/es6/my_es6/promise/data/monster.json").then((resultData) => {
           console.log("第1次请求数据=",resultData);
           return get(`data/monster_detail_${resultData.id}.json`);
        }).then((resultData)=>{
            console.log("第2次请求数据=",resultData);
            return get(`data/monster_gf_${resultData.gfid}.json`); //这里是一个promise对象，
            // 所以最后的catch 可以捕获到 这里出现的异常！！
        }).then((resultData)=>{
            console.log("第3次请求数据=",resultData);
            // 这里没有返回promise对象 但是后面的代码不会出错，只是这里出现的异常不会被catch捕获到
        }).catch((err)=>{
            console.log("promise 请求出现异常",err);
        })




    </script>
</head>
<body>

</body>
</html>